{
 "cells": [
  {
   "cell_type": "code",
   "execution_count": 4,
   "metadata": {},
   "outputs": [
    {
     "name": "stdout",
     "output_type": "stream",
     "text": [
      "Extracting MNIST_data/train-images-idx3-ubyte.gz\n",
      "Extracting MNIST_data/train-labels-idx1-ubyte.gz\n",
      "Extracting MNIST_data/t10k-images-idx3-ubyte.gz\n",
      "Extracting MNIST_data/t10k-labels-idx1-ubyte.gz\n"
     ]
    }
   ],
   "source": [
    "import numpy as np\n",
    "import matplotlib.pyplot as plt\n",
    "\n",
    "import warnings\n",
    "warnings.filterwarnings(\"ignore\")\n",
    "\n",
    "#import modules\n",
    "import tensorflow as tf\n",
    "from tensorflow.examples.tutorials.mnist import input_data\n",
    "\n",
    "# 指定使用GPU编号\n",
    "import os\n",
    "os.environ['CUDA_VISIBLE_DEVICES']='0'\n",
    "\n",
    "#import data\n",
    "mnist = input_data.read_data_sets(\"MNIST_data/\", one_hot=True)"
   ]
  },
  {
   "cell_type": "markdown",
   "metadata": {},
   "source": [
    "## 加载训练好的模型"
   ]
  },
  {
   "cell_type": "code",
   "execution_count": 5,
   "metadata": {},
   "outputs": [],
   "source": [
    "# 加载模型\n",
    "model_name = 'mycnn-' + str(1000)\n",
    "saver = tf.train.import_meta_graph('./ckpt/' + model_name + '/' + model_name + '.meta')\n"
   ]
  },
  {
   "cell_type": "markdown",
   "metadata": {},
   "source": [
    "## 测试模型"
   ]
  },
  {
   "cell_type": "code",
   "execution_count": 6,
   "metadata": {
    "scrolled": false
   },
   "outputs": [
    {
     "name": "stdout",
     "output_type": "stream",
     "text": [
      "INFO:tensorflow:Restoring parameters from ./ckpt/mycnn-1000/mycnn-1000\n"
     ]
    },
    {
     "ename": "UnknownError",
     "evalue": "Failed to get convolution algorithm. This is probably because cuDNN failed to initialize, so try looking to see if a warning log message was printed above.\n\t [[node Conv2D (defined at <ipython-input-2-42b29cc39d85>:3) ]]\n\nCaused by op 'Conv2D', defined at:\n  File \"/home/xpt/anaconda3/lib/python3.7/runpy.py\", line 193, in _run_module_as_main\n    \"__main__\", mod_spec)\n  File \"/home/xpt/anaconda3/lib/python3.7/runpy.py\", line 85, in _run_code\n    exec(code, run_globals)\n  File \"/home/xpt/anaconda3/lib/python3.7/site-packages/ipykernel_launcher.py\", line 16, in <module>\n    app.launch_new_instance()\n  File \"/home/xpt/anaconda3/lib/python3.7/site-packages/traitlets/config/application.py\", line 658, in launch_instance\n    app.start()\n  File \"/home/xpt/anaconda3/lib/python3.7/site-packages/ipykernel/kernelapp.py\", line 497, in start\n    self.io_loop.start()\n  File \"/home/xpt/anaconda3/lib/python3.7/site-packages/tornado/platform/asyncio.py\", line 132, in start\n    self.asyncio_loop.run_forever()\n  File \"/home/xpt/anaconda3/lib/python3.7/asyncio/base_events.py\", line 523, in run_forever\n    self._run_once()\n  File \"/home/xpt/anaconda3/lib/python3.7/asyncio/base_events.py\", line 1758, in _run_once\n    handle._run()\n  File \"/home/xpt/anaconda3/lib/python3.7/asyncio/events.py\", line 88, in _run\n    self._context.run(self._callback, *self._args)\n  File \"/home/xpt/anaconda3/lib/python3.7/site-packages/tornado/platform/asyncio.py\", line 122, in _handle_events\n    handler_func(fileobj, events)\n  File \"/home/xpt/anaconda3/lib/python3.7/site-packages/tornado/stack_context.py\", line 300, in null_wrapper\n    return fn(*args, **kwargs)\n  File \"/home/xpt/anaconda3/lib/python3.7/site-packages/zmq/eventloop/zmqstream.py\", line 450, in _handle_events\n    self._handle_recv()\n  File \"/home/xpt/anaconda3/lib/python3.7/site-packages/zmq/eventloop/zmqstream.py\", line 480, in _handle_recv\n    self._run_callback(callback, msg)\n  File \"/home/xpt/anaconda3/lib/python3.7/site-packages/zmq/eventloop/zmqstream.py\", line 432, in _run_callback\n    callback(*args, **kwargs)\n  File \"/home/xpt/anaconda3/lib/python3.7/site-packages/tornado/stack_context.py\", line 300, in null_wrapper\n    return fn(*args, **kwargs)\n  File \"/home/xpt/anaconda3/lib/python3.7/site-packages/ipykernel/kernelbase.py\", line 283, in dispatcher\n    return self.dispatch_shell(stream, msg)\n  File \"/home/xpt/anaconda3/lib/python3.7/site-packages/ipykernel/kernelbase.py\", line 233, in dispatch_shell\n    handler(stream, idents, msg)\n  File \"/home/xpt/anaconda3/lib/python3.7/site-packages/ipykernel/kernelbase.py\", line 399, in execute_request\n    user_expressions, allow_stdin)\n  File \"/home/xpt/anaconda3/lib/python3.7/site-packages/ipykernel/ipkernel.py\", line 208, in do_execute\n    res = shell.run_cell(code, store_history=store_history, silent=silent)\n  File \"/home/xpt/anaconda3/lib/python3.7/site-packages/ipykernel/zmqshell.py\", line 537, in run_cell\n    return super(ZMQInteractiveShell, self).run_cell(*args, **kwargs)\n  File \"/home/xpt/anaconda3/lib/python3.7/site-packages/IPython/core/interactiveshell.py\", line 2662, in run_cell\n    raw_cell, store_history, silent, shell_futures)\n  File \"/home/xpt/anaconda3/lib/python3.7/site-packages/IPython/core/interactiveshell.py\", line 2785, in _run_cell\n    interactivity=interactivity, compiler=compiler, result=result)\n  File \"/home/xpt/anaconda3/lib/python3.7/site-packages/IPython/core/interactiveshell.py\", line 2901, in run_ast_nodes\n    if self.run_code(code, result):\n  File \"/home/xpt/anaconda3/lib/python3.7/site-packages/IPython/core/interactiveshell.py\", line 2961, in run_code\n    exec(code_obj, self.user_global_ns, self.user_ns)\n  File \"<ipython-input-2-42b29cc39d85>\", line 3, in <module>\n    saver = tf.train.import_meta_graph('./ckpt/' + model_name + '/' + model_name + '.meta')\n  File \"/home/xpt/anaconda3/lib/python3.7/site-packages/tensorflow/python/training/saver.py\", line 1435, in import_meta_graph\n    meta_graph_or_file, clear_devices, import_scope, **kwargs)[0]\n  File \"/home/xpt/anaconda3/lib/python3.7/site-packages/tensorflow/python/training/saver.py\", line 1457, in _import_meta_graph_with_return_elements\n    **kwargs))\n  File \"/home/xpt/anaconda3/lib/python3.7/site-packages/tensorflow/python/framework/meta_graph.py\", line 806, in import_scoped_meta_graph_with_return_elements\n    return_elements=return_elements)\n  File \"/home/xpt/anaconda3/lib/python3.7/site-packages/tensorflow/python/util/deprecation.py\", line 507, in new_func\n    return func(*args, **kwargs)\n  File \"/home/xpt/anaconda3/lib/python3.7/site-packages/tensorflow/python/framework/importer.py\", line 442, in import_graph_def\n    _ProcessNewOps(graph)\n  File \"/home/xpt/anaconda3/lib/python3.7/site-packages/tensorflow/python/framework/importer.py\", line 235, in _ProcessNewOps\n    for new_op in graph._add_new_tf_operations(compute_devices=False):  # pylint: disable=protected-access\n  File \"/home/xpt/anaconda3/lib/python3.7/site-packages/tensorflow/python/framework/ops.py\", line 3433, in _add_new_tf_operations\n    for c_op in c_api_util.new_tf_operations(self)\n  File \"/home/xpt/anaconda3/lib/python3.7/site-packages/tensorflow/python/framework/ops.py\", line 3433, in <listcomp>\n    for c_op in c_api_util.new_tf_operations(self)\n  File \"/home/xpt/anaconda3/lib/python3.7/site-packages/tensorflow/python/framework/ops.py\", line 3325, in _create_op_from_tf_operation\n    ret = Operation(c_op, self)\n  File \"/home/xpt/anaconda3/lib/python3.7/site-packages/tensorflow/python/framework/ops.py\", line 1801, in __init__\n    self._traceback = tf_stack.extract_stack()\n\nUnknownError (see above for traceback): Failed to get convolution algorithm. This is probably because cuDNN failed to initialize, so try looking to see if a warning log message was printed above.\n\t [[node Conv2D (defined at <ipython-input-2-42b29cc39d85>:3) ]]\n",
     "output_type": "error",
     "traceback": [
      "\u001b[0;31m---------------------------------------------------------------------------\u001b[0m",
      "\u001b[0;31mUnknownError\u001b[0m                              Traceback (most recent call last)",
      "\u001b[0;32m~/anaconda3/lib/python3.7/site-packages/tensorflow/python/client/session.py\u001b[0m in \u001b[0;36m_do_call\u001b[0;34m(self, fn, *args)\u001b[0m\n\u001b[1;32m   1333\u001b[0m     \u001b[0;32mtry\u001b[0m\u001b[0;34m:\u001b[0m\u001b[0;34m\u001b[0m\u001b[0m\n\u001b[0;32m-> 1334\u001b[0;31m       \u001b[0;32mreturn\u001b[0m \u001b[0mfn\u001b[0m\u001b[0;34m(\u001b[0m\u001b[0;34m*\u001b[0m\u001b[0margs\u001b[0m\u001b[0;34m)\u001b[0m\u001b[0;34m\u001b[0m\u001b[0m\n\u001b[0m\u001b[1;32m   1335\u001b[0m     \u001b[0;32mexcept\u001b[0m \u001b[0merrors\u001b[0m\u001b[0;34m.\u001b[0m\u001b[0mOpError\u001b[0m \u001b[0;32mas\u001b[0m \u001b[0me\u001b[0m\u001b[0;34m:\u001b[0m\u001b[0;34m\u001b[0m\u001b[0m\n",
      "\u001b[0;32m~/anaconda3/lib/python3.7/site-packages/tensorflow/python/client/session.py\u001b[0m in \u001b[0;36m_run_fn\u001b[0;34m(feed_dict, fetch_list, target_list, options, run_metadata)\u001b[0m\n\u001b[1;32m   1318\u001b[0m       return self._call_tf_sessionrun(\n\u001b[0;32m-> 1319\u001b[0;31m           options, feed_dict, fetch_list, target_list, run_metadata)\n\u001b[0m\u001b[1;32m   1320\u001b[0m \u001b[0;34m\u001b[0m\u001b[0m\n",
      "\u001b[0;32m~/anaconda3/lib/python3.7/site-packages/tensorflow/python/client/session.py\u001b[0m in \u001b[0;36m_call_tf_sessionrun\u001b[0;34m(self, options, feed_dict, fetch_list, target_list, run_metadata)\u001b[0m\n\u001b[1;32m   1406\u001b[0m         \u001b[0mself\u001b[0m\u001b[0;34m.\u001b[0m\u001b[0m_session\u001b[0m\u001b[0;34m,\u001b[0m \u001b[0moptions\u001b[0m\u001b[0;34m,\u001b[0m \u001b[0mfeed_dict\u001b[0m\u001b[0;34m,\u001b[0m \u001b[0mfetch_list\u001b[0m\u001b[0;34m,\u001b[0m \u001b[0mtarget_list\u001b[0m\u001b[0;34m,\u001b[0m\u001b[0;34m\u001b[0m\u001b[0m\n\u001b[0;32m-> 1407\u001b[0;31m         run_metadata)\n\u001b[0m\u001b[1;32m   1408\u001b[0m \u001b[0;34m\u001b[0m\u001b[0m\n",
      "\u001b[0;31mUnknownError\u001b[0m: Failed to get convolution algorithm. This is probably because cuDNN failed to initialize, so try looking to see if a warning log message was printed above.\n\t [[{{node Conv2D}}]]",
      "\nDuring handling of the above exception, another exception occurred:\n",
      "\u001b[0;31mUnknownError\u001b[0m                              Traceback (most recent call last)",
      "\u001b[0;32m<ipython-input-6-22053d2b14ec>\u001b[0m in \u001b[0;36m<module>\u001b[0;34m()\u001b[0m\n\u001b[1;32m     15\u001b[0m     \u001b[0;32mfor\u001b[0m \u001b[0mimage\u001b[0m\u001b[0;34m,\u001b[0m \u001b[0mlabel\u001b[0m \u001b[0;32min\u001b[0m \u001b[0mzip\u001b[0m\u001b[0;34m(\u001b[0m\u001b[0mtest_x\u001b[0m\u001b[0;34m,\u001b[0m \u001b[0mtest_y\u001b[0m\u001b[0;34m)\u001b[0m\u001b[0;34m:\u001b[0m\u001b[0;34m\u001b[0m\u001b[0m\n\u001b[1;32m     16\u001b[0m         \u001b[0mimage\u001b[0m \u001b[0;34m=\u001b[0m \u001b[0mnp\u001b[0m\u001b[0;34m.\u001b[0m\u001b[0mreshape\u001b[0m\u001b[0;34m(\u001b[0m\u001b[0mimage\u001b[0m\u001b[0;34m,\u001b[0m \u001b[0;34m(\u001b[0m\u001b[0;36m1\u001b[0m\u001b[0;34m,\u001b[0m \u001b[0mIMG_SIZE\u001b[0m\u001b[0;34m,\u001b[0m \u001b[0mIMG_SIZE\u001b[0m\u001b[0;34m,\u001b[0m \u001b[0mIMG_CHANNEL\u001b[0m\u001b[0;34m)\u001b[0m\u001b[0;34m)\u001b[0m\u001b[0;34m\u001b[0m\u001b[0m\n\u001b[0;32m---> 17\u001b[0;31m         \u001b[0mpredict\u001b[0m \u001b[0;34m=\u001b[0m \u001b[0mnp\u001b[0m\u001b[0;34m.\u001b[0m\u001b[0margmax\u001b[0m\u001b[0;34m(\u001b[0m\u001b[0msess\u001b[0m\u001b[0;34m.\u001b[0m\u001b[0mrun\u001b[0m\u001b[0;34m(\u001b[0m\u001b[0mpred\u001b[0m\u001b[0;34m,\u001b[0m \u001b[0mfeed_dict\u001b[0m\u001b[0;34m=\u001b[0m\u001b[0;34m{\u001b[0m\u001b[0mX\u001b[0m\u001b[0;34m:\u001b[0m \u001b[0mimage\u001b[0m\u001b[0;34m}\u001b[0m\u001b[0;34m)\u001b[0m\u001b[0;34m)\u001b[0m\u001b[0;34m\u001b[0m\u001b[0m\n\u001b[0m\u001b[1;32m     18\u001b[0m \u001b[0;34m\u001b[0m\u001b[0m\n\u001b[1;32m     19\u001b[0m \u001b[0;31m#         if predict != np.argmax(label):\u001b[0m\u001b[0;34m\u001b[0m\u001b[0;34m\u001b[0m\u001b[0m\n",
      "\u001b[0;32m~/anaconda3/lib/python3.7/site-packages/tensorflow/python/client/session.py\u001b[0m in \u001b[0;36mrun\u001b[0;34m(self, fetches, feed_dict, options, run_metadata)\u001b[0m\n\u001b[1;32m    927\u001b[0m     \u001b[0;32mtry\u001b[0m\u001b[0;34m:\u001b[0m\u001b[0;34m\u001b[0m\u001b[0m\n\u001b[1;32m    928\u001b[0m       result = self._run(None, fetches, feed_dict, options_ptr,\n\u001b[0;32m--> 929\u001b[0;31m                          run_metadata_ptr)\n\u001b[0m\u001b[1;32m    930\u001b[0m       \u001b[0;32mif\u001b[0m \u001b[0mrun_metadata\u001b[0m\u001b[0;34m:\u001b[0m\u001b[0;34m\u001b[0m\u001b[0m\n\u001b[1;32m    931\u001b[0m         \u001b[0mproto_data\u001b[0m \u001b[0;34m=\u001b[0m \u001b[0mtf_session\u001b[0m\u001b[0;34m.\u001b[0m\u001b[0mTF_GetBuffer\u001b[0m\u001b[0;34m(\u001b[0m\u001b[0mrun_metadata_ptr\u001b[0m\u001b[0;34m)\u001b[0m\u001b[0;34m\u001b[0m\u001b[0m\n",
      "\u001b[0;32m~/anaconda3/lib/python3.7/site-packages/tensorflow/python/client/session.py\u001b[0m in \u001b[0;36m_run\u001b[0;34m(self, handle, fetches, feed_dict, options, run_metadata)\u001b[0m\n\u001b[1;32m   1150\u001b[0m     \u001b[0;32mif\u001b[0m \u001b[0mfinal_fetches\u001b[0m \u001b[0;32mor\u001b[0m \u001b[0mfinal_targets\u001b[0m \u001b[0;32mor\u001b[0m \u001b[0;34m(\u001b[0m\u001b[0mhandle\u001b[0m \u001b[0;32mand\u001b[0m \u001b[0mfeed_dict_tensor\u001b[0m\u001b[0;34m)\u001b[0m\u001b[0;34m:\u001b[0m\u001b[0;34m\u001b[0m\u001b[0m\n\u001b[1;32m   1151\u001b[0m       results = self._do_run(handle, final_targets, final_fetches,\n\u001b[0;32m-> 1152\u001b[0;31m                              feed_dict_tensor, options, run_metadata)\n\u001b[0m\u001b[1;32m   1153\u001b[0m     \u001b[0;32melse\u001b[0m\u001b[0;34m:\u001b[0m\u001b[0;34m\u001b[0m\u001b[0m\n\u001b[1;32m   1154\u001b[0m       \u001b[0mresults\u001b[0m \u001b[0;34m=\u001b[0m \u001b[0;34m[\u001b[0m\u001b[0;34m]\u001b[0m\u001b[0;34m\u001b[0m\u001b[0m\n",
      "\u001b[0;32m~/anaconda3/lib/python3.7/site-packages/tensorflow/python/client/session.py\u001b[0m in \u001b[0;36m_do_run\u001b[0;34m(self, handle, target_list, fetch_list, feed_dict, options, run_metadata)\u001b[0m\n\u001b[1;32m   1326\u001b[0m     \u001b[0;32mif\u001b[0m \u001b[0mhandle\u001b[0m \u001b[0;32mis\u001b[0m \u001b[0;32mNone\u001b[0m\u001b[0;34m:\u001b[0m\u001b[0;34m\u001b[0m\u001b[0m\n\u001b[1;32m   1327\u001b[0m       return self._do_call(_run_fn, feeds, fetches, targets, options,\n\u001b[0;32m-> 1328\u001b[0;31m                            run_metadata)\n\u001b[0m\u001b[1;32m   1329\u001b[0m     \u001b[0;32melse\u001b[0m\u001b[0;34m:\u001b[0m\u001b[0;34m\u001b[0m\u001b[0m\n\u001b[1;32m   1330\u001b[0m       \u001b[0;32mreturn\u001b[0m \u001b[0mself\u001b[0m\u001b[0;34m.\u001b[0m\u001b[0m_do_call\u001b[0m\u001b[0;34m(\u001b[0m\u001b[0m_prun_fn\u001b[0m\u001b[0;34m,\u001b[0m \u001b[0mhandle\u001b[0m\u001b[0;34m,\u001b[0m \u001b[0mfeeds\u001b[0m\u001b[0;34m,\u001b[0m \u001b[0mfetches\u001b[0m\u001b[0;34m)\u001b[0m\u001b[0;34m\u001b[0m\u001b[0m\n",
      "\u001b[0;32m~/anaconda3/lib/python3.7/site-packages/tensorflow/python/client/session.py\u001b[0m in \u001b[0;36m_do_call\u001b[0;34m(self, fn, *args)\u001b[0m\n\u001b[1;32m   1346\u001b[0m           \u001b[0;32mpass\u001b[0m\u001b[0;34m\u001b[0m\u001b[0m\n\u001b[1;32m   1347\u001b[0m       \u001b[0mmessage\u001b[0m \u001b[0;34m=\u001b[0m \u001b[0merror_interpolation\u001b[0m\u001b[0;34m.\u001b[0m\u001b[0minterpolate\u001b[0m\u001b[0;34m(\u001b[0m\u001b[0mmessage\u001b[0m\u001b[0;34m,\u001b[0m \u001b[0mself\u001b[0m\u001b[0;34m.\u001b[0m\u001b[0m_graph\u001b[0m\u001b[0;34m)\u001b[0m\u001b[0;34m\u001b[0m\u001b[0m\n\u001b[0;32m-> 1348\u001b[0;31m       \u001b[0;32mraise\u001b[0m \u001b[0mtype\u001b[0m\u001b[0;34m(\u001b[0m\u001b[0me\u001b[0m\u001b[0;34m)\u001b[0m\u001b[0;34m(\u001b[0m\u001b[0mnode_def\u001b[0m\u001b[0;34m,\u001b[0m \u001b[0mop\u001b[0m\u001b[0;34m,\u001b[0m \u001b[0mmessage\u001b[0m\u001b[0;34m)\u001b[0m\u001b[0;34m\u001b[0m\u001b[0m\n\u001b[0m\u001b[1;32m   1349\u001b[0m \u001b[0;34m\u001b[0m\u001b[0m\n\u001b[1;32m   1350\u001b[0m   \u001b[0;32mdef\u001b[0m \u001b[0m_extend_graph\u001b[0m\u001b[0;34m(\u001b[0m\u001b[0mself\u001b[0m\u001b[0;34m)\u001b[0m\u001b[0;34m:\u001b[0m\u001b[0;34m\u001b[0m\u001b[0m\n",
      "\u001b[0;31mUnknownError\u001b[0m: Failed to get convolution algorithm. This is probably because cuDNN failed to initialize, so try looking to see if a warning log message was printed above.\n\t [[node Conv2D (defined at <ipython-input-2-42b29cc39d85>:3) ]]\n\nCaused by op 'Conv2D', defined at:\n  File \"/home/xpt/anaconda3/lib/python3.7/runpy.py\", line 193, in _run_module_as_main\n    \"__main__\", mod_spec)\n  File \"/home/xpt/anaconda3/lib/python3.7/runpy.py\", line 85, in _run_code\n    exec(code, run_globals)\n  File \"/home/xpt/anaconda3/lib/python3.7/site-packages/ipykernel_launcher.py\", line 16, in <module>\n    app.launch_new_instance()\n  File \"/home/xpt/anaconda3/lib/python3.7/site-packages/traitlets/config/application.py\", line 658, in launch_instance\n    app.start()\n  File \"/home/xpt/anaconda3/lib/python3.7/site-packages/ipykernel/kernelapp.py\", line 497, in start\n    self.io_loop.start()\n  File \"/home/xpt/anaconda3/lib/python3.7/site-packages/tornado/platform/asyncio.py\", line 132, in start\n    self.asyncio_loop.run_forever()\n  File \"/home/xpt/anaconda3/lib/python3.7/asyncio/base_events.py\", line 523, in run_forever\n    self._run_once()\n  File \"/home/xpt/anaconda3/lib/python3.7/asyncio/base_events.py\", line 1758, in _run_once\n    handle._run()\n  File \"/home/xpt/anaconda3/lib/python3.7/asyncio/events.py\", line 88, in _run\n    self._context.run(self._callback, *self._args)\n  File \"/home/xpt/anaconda3/lib/python3.7/site-packages/tornado/platform/asyncio.py\", line 122, in _handle_events\n    handler_func(fileobj, events)\n  File \"/home/xpt/anaconda3/lib/python3.7/site-packages/tornado/stack_context.py\", line 300, in null_wrapper\n    return fn(*args, **kwargs)\n  File \"/home/xpt/anaconda3/lib/python3.7/site-packages/zmq/eventloop/zmqstream.py\", line 450, in _handle_events\n    self._handle_recv()\n  File \"/home/xpt/anaconda3/lib/python3.7/site-packages/zmq/eventloop/zmqstream.py\", line 480, in _handle_recv\n    self._run_callback(callback, msg)\n  File \"/home/xpt/anaconda3/lib/python3.7/site-packages/zmq/eventloop/zmqstream.py\", line 432, in _run_callback\n    callback(*args, **kwargs)\n  File \"/home/xpt/anaconda3/lib/python3.7/site-packages/tornado/stack_context.py\", line 300, in null_wrapper\n    return fn(*args, **kwargs)\n  File \"/home/xpt/anaconda3/lib/python3.7/site-packages/ipykernel/kernelbase.py\", line 283, in dispatcher\n    return self.dispatch_shell(stream, msg)\n  File \"/home/xpt/anaconda3/lib/python3.7/site-packages/ipykernel/kernelbase.py\", line 233, in dispatch_shell\n    handler(stream, idents, msg)\n  File \"/home/xpt/anaconda3/lib/python3.7/site-packages/ipykernel/kernelbase.py\", line 399, in execute_request\n    user_expressions, allow_stdin)\n  File \"/home/xpt/anaconda3/lib/python3.7/site-packages/ipykernel/ipkernel.py\", line 208, in do_execute\n    res = shell.run_cell(code, store_history=store_history, silent=silent)\n  File \"/home/xpt/anaconda3/lib/python3.7/site-packages/ipykernel/zmqshell.py\", line 537, in run_cell\n    return super(ZMQInteractiveShell, self).run_cell(*args, **kwargs)\n  File \"/home/xpt/anaconda3/lib/python3.7/site-packages/IPython/core/interactiveshell.py\", line 2662, in run_cell\n    raw_cell, store_history, silent, shell_futures)\n  File \"/home/xpt/anaconda3/lib/python3.7/site-packages/IPython/core/interactiveshell.py\", line 2785, in _run_cell\n    interactivity=interactivity, compiler=compiler, result=result)\n  File \"/home/xpt/anaconda3/lib/python3.7/site-packages/IPython/core/interactiveshell.py\", line 2901, in run_ast_nodes\n    if self.run_code(code, result):\n  File \"/home/xpt/anaconda3/lib/python3.7/site-packages/IPython/core/interactiveshell.py\", line 2961, in run_code\n    exec(code_obj, self.user_global_ns, self.user_ns)\n  File \"<ipython-input-2-42b29cc39d85>\", line 3, in <module>\n    saver = tf.train.import_meta_graph('./ckpt/' + model_name + '/' + model_name + '.meta')\n  File \"/home/xpt/anaconda3/lib/python3.7/site-packages/tensorflow/python/training/saver.py\", line 1435, in import_meta_graph\n    meta_graph_or_file, clear_devices, import_scope, **kwargs)[0]\n  File \"/home/xpt/anaconda3/lib/python3.7/site-packages/tensorflow/python/training/saver.py\", line 1457, in _import_meta_graph_with_return_elements\n    **kwargs))\n  File \"/home/xpt/anaconda3/lib/python3.7/site-packages/tensorflow/python/framework/meta_graph.py\", line 806, in import_scoped_meta_graph_with_return_elements\n    return_elements=return_elements)\n  File \"/home/xpt/anaconda3/lib/python3.7/site-packages/tensorflow/python/util/deprecation.py\", line 507, in new_func\n    return func(*args, **kwargs)\n  File \"/home/xpt/anaconda3/lib/python3.7/site-packages/tensorflow/python/framework/importer.py\", line 442, in import_graph_def\n    _ProcessNewOps(graph)\n  File \"/home/xpt/anaconda3/lib/python3.7/site-packages/tensorflow/python/framework/importer.py\", line 235, in _ProcessNewOps\n    for new_op in graph._add_new_tf_operations(compute_devices=False):  # pylint: disable=protected-access\n  File \"/home/xpt/anaconda3/lib/python3.7/site-packages/tensorflow/python/framework/ops.py\", line 3433, in _add_new_tf_operations\n    for c_op in c_api_util.new_tf_operations(self)\n  File \"/home/xpt/anaconda3/lib/python3.7/site-packages/tensorflow/python/framework/ops.py\", line 3433, in <listcomp>\n    for c_op in c_api_util.new_tf_operations(self)\n  File \"/home/xpt/anaconda3/lib/python3.7/site-packages/tensorflow/python/framework/ops.py\", line 3325, in _create_op_from_tf_operation\n    ret = Operation(c_op, self)\n  File \"/home/xpt/anaconda3/lib/python3.7/site-packages/tensorflow/python/framework/ops.py\", line 1801, in __init__\n    self._traceback = tf_stack.extract_stack()\n\nUnknownError (see above for traceback): Failed to get convolution algorithm. This is probably because cuDNN failed to initialize, so try looking to see if a warning log message was printed above.\n\t [[node Conv2D (defined at <ipython-input-2-42b29cc39d85>:3) ]]\n"
     ]
    }
   ],
   "source": [
    "IMG_SIZE = 28\n",
    "IMG_CHANNEL = 1\n",
    "\n",
    "\n",
    "with tf.Session() as sess:\n",
    "    saver.restore(sess, tf.train.latest_checkpoint('./ckpt/' + model_name + '/'))\n",
    "    graph = tf.get_default_graph()\n",
    "    # 获取输入和输出变量\n",
    "    X = graph.get_tensor_by_name(\"Placeholder:0\")\n",
    "    pred = graph.get_tensor_by_name(\"add_5:0\")\n",
    "\n",
    "    test_x = mnist.test.images\n",
    "    test_y = mnist.test.labels\n",
    "    \n",
    "    for image, label in zip(test_x, test_y):\n",
    "        image = np.reshape(image, (1, IMG_SIZE, IMG_SIZE, IMG_CHANNEL))\n",
    "        predict = np.argmax(sess.run(pred, feed_dict={X: image}))\n",
    "        \n",
    "#         if predict != np.argmax(label):\n",
    "        plt.imshow(image.reshape((IMG_SIZE, IMG_SIZE)), cmap='gray')\n",
    "        plt.show()\n",
    "        print('该数字真实值是%d'%(np.argmax(label)))\n",
    "        print('识别到该数字是%d\\n'%(predict))"
   ]
  },
  {
   "cell_type": "code",
   "execution_count": null,
   "metadata": {},
   "outputs": [],
   "source": []
  }
 ],
 "metadata": {
  "kernelspec": {
   "display_name": "Python 3",
   "language": "python",
   "name": "python3"
  },
  "language_info": {
   "codemirror_mode": {
    "name": "ipython",
    "version": 3
   },
   "file_extension": ".py",
   "mimetype": "text/x-python",
   "name": "python",
   "nbconvert_exporter": "python",
   "pygments_lexer": "ipython3",
   "version": "3.7.0"
  }
 },
 "nbformat": 4,
 "nbformat_minor": 2
}
